Workbook

Sheet Cover
B15: 1 | C15: Assumptions
B16: 2 | C16: Methodology
B17: 3 | C17: Inventory Register
B18: 4 | C18: FIFO vs Weighted Avg
B19: 5 | C19: Standard Costing & Variances
B20: 6 | C20: Consignment & Cutoff
B21: 7 | C21: Intercompany Elimination
B22: 8 | C22: Pledged Collateral
B23: 9 | C23: Borrowing Cost Capitalization
B24: 10 | C24: Disclosures Summary
B25: 11 | C25: Visualizations
B26: 12 | C26: Checks & Audit
B27: 13 | C27: Glossary

Sheet Assumptions
A1: IAS 2 Inventory Model - Assumptions
A2: Ghana-domiciled entity, GHS functional/presentation currency. Each inventory line carries its own Industry Profile tag, and the parameters below drive that profiles costing/NRV mechanics via lookup - so all five profiles mechanics are visible side by side in one dataset.
A4: USD/GHS Rate (for foreign-currency-denominated purchases, historical rate only - IAS 21 non-monetary) | B4: 10.8
A6: Industry Profile Parameters
A7: Profile | B7: Costing Method | C7: Currency | D7: Avg Gross Margin % | E7: Aging Threshold - Fast (days) | F7: Provision % - 91-180d | G7: Provision % - 181-365d | H7: Provision % - 365d+
A8: Manufacturing | B8: Weighted Average | C8: GHS | D8: 0.28 | E8: 90 | F8: 0.05 | G8: 0.2 | H8: 0.6
A9: Retail/FMCG | B9: Weighted Average | C9: GHS | D9: 0.35 | E9: 90 | F9: 0.1 | G9: 0.35 | H9: 0.8
A10: Real Estate Developer | B10: Specific Identification | C10: GHS | D10: 0.22 | E10: 90 | F10: 0 | G10: 0.05 | H10: 0.15
A11: Agribusiness/Commodity | B11: Fair Value Less Costs to Sell | C11: USD | D11: 0.12 | E11: 90 | F11: 0.02 | G11: 0.1 | H11: 0.4
A12: Extractives | B12: FIFO | C12: USD | D12: 0.18 | E12: 90 | F12: 0.03 | G12: 0.15 | H12: 0.5

Sheet Methodology
A1: IAS 2 Model - Methodology Notes
A2: 1. Industry profile adaptation
A3: Rather than a single live on/off switch (impractical to demonstrate meaningfully across 10,000+ rows), each inventory line carries its own Industry Profile tag, with per-profile costing method, margin, and aging-provision parameters on the Assumptions sheet driving that rows mechanics via INDEX/MATCH lookup. This shows all five profiles practical outcomes side by side rather than one at a time.
A5: 2. Cost determination
A6: Total Cost = Quantity x Unit Cost, converted to GHS at the historical rate for foreign-currency purchases (IAS 21 non-monetary treatment - never retranslated). NRV = Quantity x (Selling Price - Costs to Complete - Costs to Sell), tested item-by-item, never by total class.
A8: 3. Aging and provisioning
A9: Days Held = todays date less purchase date, bucketed into 0-90/91-180/181-365/365+ days, each bucket carrying its own provision % by industry profile. Carrying Amount = MIN(Cost less aging provision, NRV) - the lower of cost and NRV, per item.
A11: 4. FIFO vs Weighted Average
A12: Modelled on a 150-SKU representative sample with 3-5 purchase layers each, rather than multi-layer tracking across the full 10,000+ line register (which would require carrying full purchase history per SKU at a scale that adds complexity without adding insight into the mechanic itself). LIFO is prohibited under IFRS and is not modelled.
A14: 5. Consignment, cutoff, and intercompany
A15: Consignment status flags exclude goods held but not owned from the entitys own carrying amount. Cutoff testing compares FOB shipping point vs destination terms against the period-end date to flag misstatement risk. Intercompany elimination removes unrealized profit still sitting in a buyers closing inventory from an intragroup sale.
A17: 6. Borrowing cost capitalization
... A21: All data is synthetic, for training/practice purposes only. Margin, provisioning, and rate assumptions are illustrative starting points - validate against your own institutions actual cost data, aging history, and borrowing arrangements before using this structure for anything other than practice.

Sheet Inventory Register
A1: SKU/Batch ID | B1: Industry Profile | C1: Category | D1: Purchase Date | E1: Quantity | F1: Currency | G1: Unit Cost | H1: Total Cost (Local Ccy) | I1: Total Cost (GHS) | J1: Costing Method | K1: Selling Price (Unit) | L1: Costs to Complete (Unit) | M1: Costs to Sell (Unit) | N1: NRV (Total, GHS) | O1: Days Held | P1: Aging Bucket | Q1: Provision % | R1: Provision Amount (GHS) | S1: Carrying Amount (Lower of Cost/NRV, GHS) | T1: Consignment Status | U1: Pledged as Collateral?
A2: EXT-900000 | B2: Extractives | C2: Ore Stockpile | D2: 45948 | E2: 2935 | F2: USD | G2: 19467 | H2: =E2*G2 -> 57135645 | I2: =IF(F2="GHS",H2,H2*Assumptions!$B$4) -> 617064966 | J2: =INDEX(Assumptions!$B$8:$B$12,MATCH(B2,Assumptions!$A$8:$A$12,0)) -> FIFO | K2: =G2/(1-INDEX(Assumptions!$D$8:$D$12,MATCH(B2,Assumptions!$A$8:$A$12,0))) -> 23740.244 | L2: =G2*0.03 -> 584.01 | M2: =K2*0.05 -> 1187.0122 | N2: =E2*(K2-L2-M2)*IF(F2="GHS",1,Assumptions!$B$4) -> 6.9638039e+08 | O2: =TODAY()-D2 -> 338 | P2: =IF(O2<=90,"0-90d",IF(O2<=180,"91-180d",IF(O2<=365,"181-365d","365d+"))) -> 181-365d | Q2: =IF(P2="0-90d",0,IF(P2="91-180d",INDEX(Assumptions!$F$8:$F$12,MATCH(B2,Assumptions!$A$8:$A$12,0)),IF(P2="181-365d",INDEX(Assumptions!$G$8:$G$12,MATCH(B2,Assumptions!$A$8:$A$12,0)),INDEX(Assumptions!$H$8:$H$12,MATCH(B2,Assumptions!$A$8:$A$12,0))))) -> 0.15 | R2: =I2*Q2 -> 92559745 | S2: =IF(T2="Held on Consignment (Not Owned)",0,MIN(I2-R2,N2)) -> 5.2450522e+08 | T2: Owned | U2: No
A3: AGR-900001 | B3: Agribusiness/Commodity | C3: Cashew | D3: 46013 | E3: 1804 | F3: USD | G3: 8134.61 | H3: =E3*G3 -> 14674836 | I3: =IF(F3="GHS",H3,H3*Assumptions!$B$4) -> 1.5848823e+08 | J3: =INDEX(Assumptions!$B$8:$B$12,MATCH(B3,Assumptions!$A$8:$A$12,0)) -> Fair Value Less Costs to Sell | K3: =G3/(1-INDEX(Assumptions!$D$8:$D$12,MATCH(B3,Assumptions!$A$8:$A$12,0))) -> 9243.875 | L3: =G3*0.03 -> 244.0383 | M3: =K3*0.05 -> 462.19375 | N3: =E3*(K3-L3-M3)*IF(F3="GHS",1,Assumptions!$B$4) -> 1.6634061e+08 | O3: =TODAY()-D3 -> 273 | P3: =IF(O3<=90,"0-90d",IF(O3<=180,"91-180d",IF(O3<=365,"181-365d","365d+"))) -> 181-365d | Q3: =IF(P3="0-90d",0,IF(P3="91-180d",INDEX(Assumptions!$F$8:$F$12,MATCH(B3,Assumptions!$A$8:$A$12,0)),IF(P3="181-365d",INDEX(Assumptions!$G$8:$G$12,MATCH(B3,Assumptions!$A$8:$A$12,0)),INDEX(Assumptions!$H$8:$H$12,MATCH(B3,Assumptions!$A$8:$A$12,0))))) -> 0.1 | R3: =I3*Q3 -> 15848823 | S3: =IF(T3="Held on Consignment (Not Owned)",0,MIN(I3-R3,N3)) -> 1.4263941e+08 | T3: Owned | U3: No
A4: MAN-900002 | B4: Manufacturing | C4: Work-in-Progress | D4: 45893 | E4: 2485 | F4: GHS | G4: 3576.45 | H4: =E4*G4 -> 8887478.2 | I4: =IF(F4="GHS",H4,H4*Assumptions!$B$4) -> 8887478.2 | J4: =INDEX(Assumptions!$B$8:$B$12,MATCH(B4,Assumptions!$A$8:$A$12,0)) -> Weighted Average | K4: =G4/(1-INDEX(Assumptions!$D$8:$D$12,MATCH(B4,Assumptions!$A$8:$A$12,0))) -> 4967.2917 | L4: =G4*0.03 -> 107.2935 | M4: =K4*0.05 -> 248.36458 | N4: =E4*(K4-L4-M4)*IF(F4="GHS",1,Assumptions!$B$4) -> 11459909 | O4: =TODAY()-D4 -> 393 | P4: =IF(O4<=90,"0-90d",IF(O4<=180,"91-180d",IF(O4<=365,"181-365d","365d+"))) -> 365d+ | Q4: =IF(P4="0-90d",0,IF(P4="91-180d",INDEX(Assumptions!$F$8:$F$12,MATCH(B4,Assumptions!$A$8:$A$12,0)),IF(P4="181-365d",INDEX(Assumptions!$G$8:$G$12,MATCH(B4,Assumptions!$A$8:$A$12,0)),INDEX(Assumptions!$H$8:$H$12,MATCH(B4,Assumptions!$A$8:$A$12,0))))) -> 0.6 | R4: =I4*Q4 -> 5332487 | S4: =IF(T4="Held on Consignment (Not Owned)",0,MIN(I4-R4,N4)) -> 3554991.3 | T4: Owned | U4: No
A5: AGR-900003 | B5: Agribusiness/Commodity | C5: Maize | D5: 46109 | E5: 3757 | F5: USD | G5: 8134.3 | H5: =E5*G5 -> 30560565 | I5: =IF(F5="GHS",H5,H5*Assumptions!$B$4) -> 3.300541e+08 | J5: =INDEX(Assumptions!$B$8:$B$12,MATCH(B5,Assumptions!$A$8:$A$12,0)) -> Fair Value Less Costs to Sell | K5: =G5/(1-INDEX(Assumptions!$D$8:$D$12,MATCH(B5,Assumptions!$A$8:$A$12,0))) -> 9243.5227 | L5: =G5*0.03 -> 244.029 | M5: =K5*0.05 -> 462.17614 | N5: =E5*(K5-L5-M5)*IF(F5="GHS",1,Assumptions!$B$4) -> 3.4640678e+08 | O5: =TODAY()-D5 -> 177 | P5: =IF(O5<=90,"0-90d",IF(O5<=180,"91-180d",IF(O5<=365,"181-365d","365d+"))) -> 91-180d | Q5: =IF(P5="0-90d",0,IF(P5="91-180d",INDEX(Assumptions!$F$8:$F$12,MATCH(B5,Assumptions!$A$8:$A$12,0)),IF(P5="181-365d",INDEX(Assumptions!$G$8:$G$12,MATCH(B5,Assumptions!$A$8:$A$12,0)),INDEX(Assumptions!$H$8:$H$12,MATCH(B5,Assumptions!$A$8:$A$12,0))))) -> 0.02 | R5: =I5*Q5 -> 6601082.1 | S5: =IF(T5="Held on Consignment (Not Owned)",0,MIN(I5-R5,N5)) -> 3.2345302e+08 | T5: Owned | U5: Yes
A6: AGR-900004 | B6: Agribusiness/Commodity | C6: Shea | D6: 46116 | E6: 57 | F6: USD | G6: 11465.23 | H6: =E6*G6 -> 653518.11 | I6: =IF(F6="GHS",H6,H6*Assumptions!$B$4) -> 7057995.6 | J6: =INDEX(Assumptions!$B$8:$B$12,MATCH(B6,Assumptions!$A$8:$A$12,0)) -> Fair Value Less Costs to Sell | K6: =G6/(1-INDEX(Assumptions!$D$8:$D$12,MATCH(B6,Assumptions!$A$8:$A$12,0))) -> 13028.67 | L6: =G6*0.03 -> 343.9569 | M6: =K6*0.05 -> 651.43352 | N6: =E6*(K6-L6-M6)*IF(F6="GHS",1,Assumptions!$B$4) -> 7407687.2 | O6: =TODAY()-D6 -> 170 | P6: =IF(O6<=90,"0-90d",IF(O6<=180,"91-180d",IF(O6<=365,"181-365d","365d+"))) -> 91-180d | Q6: =IF(P6="0-90d",0,IF(P6="91-180d",INDEX(Assumptions!$F$8:$F$12,MATCH(B6,Assumptions!$A$8:$A$12,0)),IF(P6="181-365d",INDEX(Assumptions!$G$8:$G$12,MATCH(B6,Assumptions!$A$8:$A$12,0)),INDEX(Assumptions!$H$8:$H$12,MATCH(B6,Assumptions!$A$8:$A$12,0))))) -> 0.02 | R6: =I6*Q6 -> 141159.91 | S6: =IF(T6="Held on Consignment (Not Owned)",0,MIN(I6-R6,N6)) -> 0 | T6: Held on Consignment (Not Owned) | U6: No
A7: RET-900005 | B7: Retail/FMCG | C7: Personal Care | D7: 46200 | E7: 3179 | F7: GHS | G7: 205.14 | H7: =E7*G7 -> 652140.06 | I7: =IF(F7="GHS",H7,H7*Assumptions!$B$4) -> 652140.06 | J7: =INDEX(Assumptions!$B$8:$B$12,MATCH(B7,Assumptions!$A$8:$A$12,0)) -> Weighted Average | K7: =G7/(1-INDEX(Assumptions!$D$8:$D$12,MATCH(B7,Assumptions!$A$8:$A$12,0))) -> 315.6 | L7: =G7*0.03 -> 6.1542 | M7: =K7*0.05 -> 15.78 | N7: =E7*(K7-L7-M7)*IF(F7="GHS",1,Assumptions!$B$4) -> 933563.58 | O7: =TODAY()-D7 -> 86 | P7: =IF(O7<=90,"0-90d",IF(O7<=180,"91-180d",IF(O7<=365,"181-365d","365d+"))) -> 0-90d | Q7: =IF(P7="0-90d",0,IF(P7="91-180d",INDEX(Assumptions!$F$8:$F$12,MATCH(B7,Assumptions!$A$8:$A$12,0)),IF(P7="181-365d",INDEX(Assumptions!$G$8:$G$12,MATCH(B7,Assumptions!$A$8:$A$12,0)),INDEX(Assumptions!$H$8:$H$12,MATCH(B7,Assumptions!$A$8:$A$12,0))))) -> 0 | R7: =I7*Q7 -> 0 | S7: =IF(T7="Held on Consignment (Not Owned)",0,MIN(I7-R7,N7)) -> 652140.06 | T7: Owned | U7: Yes
A8: RET-900006 | B8: Retail/FMCG | C8: Packaged Foods | D8: 45966 | E8: 4663 | F8: GHS | G8: 445.41 | H8: =E8*G8 -> 2076946.8 | I8: =IF(F8="GHS",H8,H8*Assumptions!$B$4) -> 2076946.8 | J8: =INDEX(Assumptions!$B$8:$B$12,MATCH(B8,Assumptions!$A$8:$A$12,0)) -> Weighted Average | K8: =G8/(1-INDEX(Assumptions!$D$8:$D$12,MATCH(B8,Assumptions!$A$8:$A$12,0))) -> 685.24615 | L8: =G8*0.03 -> 13.3623 | M8: =K8*0.05 -> 34.262308 | N8: =E8*(K8-L8-M8)*IF(F8="GHS",1,Assumptions!$B$4) -> 2973229.3 | O8: =TODAY()-D8 -> 320 | P8: =IF(O8<=90,"0-90d",IF(O8<=180,"91-180d",IF(O8<=365,"181-365d","365d+"))) -> 181-365d | Q8: =IF(P8="0-90d",0,IF(P8="91-180d",INDEX(Assumptions!$F$8:$F$12,MATCH(B8,Assumptions!$A$8:$A$12,0)),IF(P8="181-365d",INDEX(Assumptions!$G$8:$G$12,MATCH(B8,Assumptions!$A$8:$A$12,0)),INDEX(Assumptions!$H$8:$H$12,MATCH(B8,Assumptions!$A$8:$A$12,0))))) -> 0.35 | R8: =I8*Q8 -> 726931.39 | S8: =IF(T8="Held on Consignment (Not Owned)",0,MIN(I8-R8,N8)) -> 1350015.4 | T8: Owned | U8: Yes
A9: REA-900007 | B9: Real Estate Developer | C9: Completed Units | D9: 46197 | E9: 2734 | F9: GHS | G9: 897884.18 | H9: =E9*G9 -> 2.4548153e+09 | I9: =IF(F9="GHS",H9,H9*Assumptions!$B$4) -> 2.4548153e+09 | J9: =INDEX(Assumptions!$B$8:$B$12,MATCH(B9,Assumptions!$A$8:$A$12,0)) -> Specific Identification | K9: =G9/(1-INDEX(Assumptions!$D$8:$D$12,MATCH(B9,Assumptions!$A$8:$A$12,0))) -> 1151133.6 | L9: =G9*0.03 -> 26936.525 | M9: =K9*0.05 -> 57556.678 | N9: =E9*(K9-L9-M9)*IF(F9="GHS",1,Assumptions!$B$4) -> 2.9161947e+09 | O9: =TODAY()-D9 -> 89 | P9: =IF(O9<=90,"0-90d",IF(O9<=180,"91-180d",IF(O9<=365,"181-365d","365d+"))) -> 0-90d | Q9: =IF(P9="0-90d",0,IF(P9="91-180d",INDEX(Assumptions!$F$8:$F$12,MATCH(B9,Assumptions!$A$8:$A$12,0)),IF(P9="181-365d",INDEX(Assumptions!$G$8:$G$12,MATCH(B9,Assumptions!$A$8:$A$12,0)),INDEX(Assumptions!$H$8:$H$12,MATCH(B9,Assumptions!$A$8:$A$12,0))))) -> 0 | R9: =I9*Q9 -> 0 | S9: =IF(T9="Held on Consignment (Not Owned)",0,MIN(I9-R9,N9)) -> 2.4548153e+09 | T9: Owned | U9: No
A10: RET-900008 | B10: Retail/FMCG | C10: Beverages | D10: 45922 | E10: 4706 | F10: GHS | G10: 346.41 | H10: =E10*G10 -> 1630205.5 | I10: =IF(F10="GHS",H10,H10*Assumptions!$B$4) -> 1630205.5 | J10: =INDEX(Assumptions!$B$8:$B$12,MATCH(B10,Assumptions!$A$8:$A$12,0)) -> Weighted Average | K10: =G10/(1-INDEX(Assumptions!$D$8:$D$12,MATCH(B10,Assumptions!$A$8:$A$12,0))) -> 532.93846 | L10: =G10*0.03 -> 10.3923 | M10: =K10*0.05 -> 26.646923 | N10: =E10*(K10-L10-M10)*IF(F10="GHS",1,Assumptions!$B$4) -> 2333701.8 | O10: =TODAY()-D10 -> 364 | P10: =IF(O10<=90,"0-90d",IF(O10<=180,"91-180d",IF(O10<=365,"181-365d","365d+"))) -> 181-365d | Q10: =IF(P10="0-90d",0,IF(P10="91-180d",INDEX(Assumptions!$F$8:$F$12,MATCH(B10,Assumptions!$A$8:$A$12,0)),IF(P10="181-365d",INDEX(Assumptions!$G$8:$G$12,MATCH(B10,Assumptions!$A$8:$A$12,0)),INDEX(Assumptions!$H$8:$H$12,MATCH(B10,Assumptions!$A$8:$A$12,0))))) -> 0.35 | R10: =I10*Q10 -> 570571.91 | S10: =IF(T10="Held on Consignment (Not Owned)",0,MIN(I10-R10,N10)) -> 1059633.5 | T10: Owned, Held Externally | U10: No
A11: REA-900009 | B11: Real Estate Developer | C11: Development WIP | D11: 46010 | E11: 672 | F11: GHS | G11: 281116.45 | H11: =E11*G11 -> 1.8891025e+08 | I11: =IF(F11="GHS",H11,H11*Assumptions!$B$4) -> 1.8891025e+08 | J11: =INDEX(Assumptions!$B$8:$B$12,MATCH(B11,Assumptions!$A$8:$A$12,0)) -> Specific Identification | K11: =G11/(1-INDEX(Assumptions!$D$8:$D$12,MATCH(B11,Assumptions!$A$8:$A$12,0))) -> 360405.71 | L11: =G11*0.03 -> 8433.4935 | M11: =K11*0.05 -> 18020.285 | N11: =E11*(K11-L11-M11)*IF(F11="GHS",1,Assumptions!$B$4) -> 2.2441569e+08 | O11: =TODAY()-D11 -> 276 | P11: =IF(O11<=90,"0-90d",IF(O11<=180,"91-180d",IF(O11<=365,"181-365d","365d+"))) -> 181-365d | Q11: =IF(P11="0-90d",0,IF(P11="91-180d",INDEX(Assumptions!$F$8:$F$12,MATCH(B11,Assumptions!$A$8:$A$12,0)),IF(P11="181-365d",INDEX(Assumptions!$G$8:$G$12,MATCH(B11,Assumptions!$A$8:$A$12,0)),INDEX(Assumptions!$H$8:$H$12,MATCH(B11,Assumptions!$A$8:$A$12,0))))) -> 0.05 | R11: =I11*Q11 -> 9445512.7 | S11: =IF(T11="Held on Consignment (Not Owned)",0,MIN(I11-R11,N11)) -> 0 | T11: Held on Consignment (Not Owned) | U11: No
A12: AGR-900010 | B12: Agribusiness/Commodity | C12: Shea | D12: 46222 | E12: 2965 | F12: USD | G12: 4301.31 | H12: =E12*G12 -> 12753384 | I12: =IF(F12="GHS",H12,H12*Assumptions!$B$4) -> 1.3773655e+08 | J12: =INDEX(Assumptions!$B$8:$B$12,MATCH(B12,Assumptions!$A$8:$A$12,0)) -> Fair Value Less Costs to Sell | K12: =G12/(1-INDEX(Assumptions!$D$8:$D$12,MATCH(B12,Assumptions!$A$8:$A$12,0))) -> 4887.8523 | L12: =G12*0.03 -> 129.0393 | M12: =K12*0.05 -> 244.39261 | N12: =E12*(K12-L12-M12)*IF(F12="GHS",1,Assumptions!$B$4) -> 1.4456077e+08 | O12: =TODAY()-D12 -> 64 | P12: =IF(O12<=90,"0-90d",IF(O12<=180,"91-180d",IF(O12<=365,"181-365d","365d+"))) -> 0-90d | Q12: =IF(P12="0-90d",0,IF(P12="91-180d",INDEX(Assumptions!$F$8:$F$12,MATCH(B12,Assumptions!$A$8:$A$12,0)),IF(P12="181-365d",INDEX(Assumptions!$G$8:$G$12,MATCH(B12,Assumptions!$A$8:$A$12,0)),INDEX(Assumptions!$H$8:$H$12,MATCH(B12,Assumptions!$A$8:$A$12,0))))) -> 0 | R12: =I12*Q12 -> 0 | S12: =IF(T12="Held on Consignment (Not Owned)",0,MIN(I12-R12,N12)) -> 1.3773655e+08 | T12: Owned | U12: No
A13: AGR-900011 | B13: Agribusiness/Commodity | C13: Cocoa | D13: 46132 | E13: 383 | F13: USD | G13: 4203.29 | H13: =E13*G13 -> 1609860.1 | I13: =IF(F13="GHS",H13,H13*Assumptions!$B$4) -> 17386489 | J13: =INDEX(Assumptions!$B$8:$B$12,MATCH(B13,Assumptions!$A$8:$A$12,0)) -> Fair Value Less Costs to Sell | K13: =G13/(1-INDEX(Assumptions!$D$8:$D$12,MATCH(B13,Assumptions!$A$8:$A$12,0))) -> 4776.4659 | L13: =G13*0.03 -> 126.0987 | M13: =K13*0.05 -> 238.8233 | N13: =E13*(K13-L13-M13)*IF(F13="GHS",1,Assumptions!$B$4) -> 18247910 | O13: =TODAY()-D13 -> 154 | P13: =IF(O13<=90,"0-90d",IF(O13<=180,"91-180d",IF(O13<=365,"181-365d","365d+"))) -> 91-180d | Q13: =IF(P13="0-90d",0,IF(P13="91-180d",INDEX(Assumptions!$F$8:$F$12,MATCH(B13,Assumptions!$A$8:$A$12,0)),IF(P13="181-365d",INDEX(Assumptions!$G$8:$G$12,MATCH(B13,Assumptions!$A$8:$A$12,0)),INDEX(Assumptions!$H$8:$H$12,MATCH(B13,Assumptions!$A$8:$A$12,0))))) -> 0.02 | R13: =I13*Q13 -> 347729.78 | S13: =IF(T13="Held on Consignment (Not Owned)",0,MIN(I13-R13,N13)) -> 17038759 | T13: Owned | U13: No
... A10501: AGR-910499 | B10501: Agribusiness/Commodity | C10501: Cashew | D10501: 45751 | E10501: 1749 | F10501: USD | G10501: 3235.5 | H10501: =E10501*G10501 -> 5658889.5 | I10501: =IF(F10501="GHS",H10501,H10501*Assumptions!$B$4) -> 61116007 | J10501: =INDEX(Assumptions!$B$8:$B$12,MATCH(B10501,Assumptions!$A$8:$A$12,0)) -> Fair Value Less Costs to Sell | K10501: =G10501/(1-INDEX(Assumptions!$D$8:$D$12,MATCH(B10501,Assumptions!$A$8:$A$12,0))) -> 3676.7045 | L10501: =G10501*0.03 -> 97.065 | M10501: =K10501*0.05 -> 183.83523 | N10501: =E10501*(K10501-L10501-M10501)*IF(F10501="GHS",1,Assumptions!$B$4) -> 64144027 | O10501: =TODAY()-D10501 -> 535 | P10501: =IF(O10501<=90,"0-90d",IF(O10501<=180,"91-180d",IF(O10501<=365,"181-365d","365d+"))) -> 365d+ | Q10501: =IF(P10501="0-90d",0,IF(P10501="91-180d",INDEX(Assumptions!$F$8:$F$12,MATCH(B10501,Assumptions!$A$8:$A$12,0)),IF(P10501="181-365d",INDEX(Assumptions!$G$8:$G$12,MATCH(B10501,Assumptions!$A$8:$A$12,0)),INDEX(Assumptions!$H$8:$H$12,MATCH(B10501,Assumptions!$A$8:$A$12,0))))) -> 0.4 | R10501: =I10501*Q10501 -> 24446403 | S10501: =IF(T10501="Held on Consignment (Not Owned)",0,MIN(I10501-R10501,N10501)) -> 36669604 | T10501: Owned | U10501: No

Sheet FIFO vs Weighted Avg
A1: FIFO vs Weighted Average Cost Comparison - Purchase Layers
A2: Demonstrates both cost formulas on multi-layer purchase histories for a sample of SKUs (LIFO is prohibited under IFRS and is not modelled). Each SKU below has 3-5 purchase layers at different unit costs; an issue quantity is tested against both methods.
H3: Issue Test - FIFO vs Weighted Average
A4: SKU | B4: Layer | C4: Purchase Date | D4: Layer Qty | E4: Layer Unit Cost (GHS) | F4: Layer Total Cost (GHS) | H4: SKU | I4: Total Qty Available | J4: Total Cost Available (GHS) | K4: Weighted Avg Unit Cost | L4: Issue Qty Tested | M4: FIFO Issue Cost (GHS) | N4: Weighted Avg Issue Cost (GHS) | O4: Variance (GHS)
A5: SAMPLE-2000 | B5: 1 | C5: 46127 | D5: 880 | E5: 1796.96 | F5: =D5*E5 -> 1581324.8 | H5: SAMPLE-2000 | I5: =SUMIFS(Table2[Layer Qty],Table2[SKU],H5) -> 3391 | J5: =SUMIFS(Table2[Layer Total Cost (GHS)],Table2[SKU],H5) -> 5587043.9 | K5: =J5/I5 -> 1647.6095 | L5: =ROUND(I5*0.6,0) -> 2035 | M5: =MIN(D5,MAX(L5-(0),0))*E5+MIN(D6,MAX(L5-(D5),0))*E6+MIN(D7,MAX(L5-(D5+D6),0))*E7+MIN(D8,MAX(L5-(D5+D6+D7),0))*E8 -> 3242214.9 | N5: =L5*K5 -> 3352885.4 | O5: =N5-M5 -> 110670.52
A6: SAMPLE-2000 | B6: 2 | C6: 46075 | D6: 908 | E6: 1417.56 | F6: =D6*E6 -> 1287144.5 | H6: SAMPLE-2001 | I6: =SUMIFS(Table2[Layer Qty],Table2[SKU],H6) -> 1099 | J6: =SUMIFS(Table2[Layer Total Cost (GHS)],Table2[SKU],H6) -> 779221.54 | K6: =J6/I6 -> 709.02779 | L6: =ROUND(I6*0.6,0) -> 659 | M6: =MIN(D9,MAX(L6-(0),0))*E9+MIN(D10,MAX(L6-(D9),0))*E10+MIN(D11,MAX(L6-(D9+D10),0))*E11+MIN(D12,MAX(L6-(D9+D10+D11),0))*E12 -> 453921.94 | N6: =L6*K6 -> 467249.31 | O6: =N6-M6 -> 13327.373
A7: SAMPLE-2000 | B7: 3 | C7: 46187 | D7: 963 | E7: 1513.14 | F7: =D7*E7 -> 1457153.8 | H7: SAMPLE-2002 | I7: =SUMIFS(Table2[Layer Qty],Table2[SKU],H7) -> 1667 | J7: =SUMIFS(Table2[Layer Total Cost (GHS)],Table2[SKU],H7) -> 2073494 | K7: =J7/I7 -> 1243.8476 | L7: =ROUND(I7*0.6,0) -> 1000 | M7: =MIN(D13,MAX(L7-(0),0))*E13+MIN(D14,MAX(L7-(D13),0))*E14+MIN(D15,MAX(L7-(D13+D14),0))*E15+MIN(D16,MAX(L7-(D13+D14+D15),0))*E16 -> 1258516.9 | N7: =L7*K7 -> 1243847.6 | O7: =N7-M7 -> -14669.262
A8: SAMPLE-2000 | B8: 4 | C8: 46138 | D8: 640 | E8: 1970.97 | F8: =D8*E8 -> 1261420.8 | H8: SAMPLE-2003 | I8: =SUMIFS(Table2[Layer Qty],Table2[SKU],H8) -> 2675 | J8: =SUMIFS(Table2[Layer Total Cost (GHS)],Table2[SKU],H8) -> 3604842.2 | K8: =J8/I8 -> 1347.6046 | L8: =ROUND(I8*0.6,0) -> 1605 | M8: =MIN(D17,MAX(L8-(0),0))*E17+MIN(D18,MAX(L8-(D17),0))*E18+MIN(D19,MAX(L8-(D17+D18),0))*E19+MIN(D20,MAX(L8-(D17+D18+D19),0))*E20+MIN(D21,MAX(L8-(D17+D18+D19+D20),0))*E21 -> 2191002.5 | N8: =L8*K8 -> 2162905.3 | O8: =N8-M8 -> -28097.174
A9: SAMPLE-2001 | B9: 1 | C9: 46129 | D9: 343 | E9: 671.58 | F9: =D9*E9 -> 230351.94 | H9: SAMPLE-2004 | I9: =SUMIFS(Table2[Layer Qty],Table2[SKU],H9) -> 2486 | J9: =SUMIFS(Table2[Layer Total Cost (GHS)],Table2[SKU],H9) -> 4108461.5 | K9: =J9/I9 -> 1652.6394 | L9: =ROUND(I9*0.6,0) -> 1492 | M9: =MIN(D22,MAX(L9-(0),0))*E22+MIN(D23,MAX(L9-(D22),0))*E23+MIN(D24,MAX(L9-(D22+D23),0))*E24+MIN(D25,MAX(L9-(D22+D23+D24),0))*E25 -> 2482730.6 | N9: =L9*K9 -> 2465738 | O9: =N9-M9 -> -16992.676
A10: SAMPLE-2001 | B10: 2 | C10: 45958 | D10: 460 | E10: 707.5 | F10: =D10*E10 -> 325450 | H10: SAMPLE-2005 | I10: =SUMIFS(Table2[Layer Qty],Table2[SKU],H10) -> 1642 | J10: =SUMIFS(Table2[Layer Total Cost (GHS)],Table2[SKU],H10) -> 3693697.8 | K10: =J10/I10 -> 2249.5114 | L10: =ROUND(I10*0.6,0) -> 985 | M10: =MIN(D26,MAX(L10-(0),0))*E26+MIN(D27,MAX(L10-(D26),0))*E27+MIN(D28,MAX(L10-(D26+D27),0))*E28 -> 2072852.5 | N10: =L10*K10 -> 2215768.8 | O10: =N10-M10 -> 142916.26
A11: SAMPLE-2001 | B11: 3 | C11: 46245 | D11: 138 | E11: 677.44 | F11: =D11*E11 -> 93486.72 | H11: SAMPLE-2006 | I11: =SUMIFS(Table2[Layer Qty],Table2[SKU],H11) -> 3692 | J11: =SUMIFS(Table2[Layer Total Cost (GHS)],Table2[SKU],H11) -> 1716974.6 | K11: =J11/I11 -> 465.0527 | L11: =ROUND(I11*0.6,0) -> 2215 | M11: =MIN(D29,MAX(L11-(0),0))*E29+MIN(D30,MAX(L11-(D29),0))*E30+MIN(D31,MAX(L11-(D29+D30),0))*E31+MIN(D32,MAX(L11-(D29+D30+D31),0))*E32+MIN(D33,MAX(L11-(D29+D30+D31+D32),0))*E33 -> 1022875.4 | N11: =L11*K11 -> 1030091.7 | O11: =N11-M11 -> 7216.2975
A12: SAMPLE-2001 | B12: 4 | C12: 46003 | D12: 158 | E12: 822.36 | F12: =D12*E12 -> 129932.88 | H12: SAMPLE-2007 | I12: =SUMIFS(Table2[Layer Qty],Table2[SKU],H12) -> 2374 | J12: =SUMIFS(Table2[Layer Total Cost (GHS)],Table2[SKU],H12) -> 2747732.7 | K12: =J12/I12 -> 1157.4274 | L12: =ROUND(I12*0.6,0) -> 1424 | M12: =MIN(D34,MAX(L12-(0),0))*E34+MIN(D35,MAX(L12-(D34),0))*E35+MIN(D36,MAX(L12-(D34+D35),0))*E36+MIN(D37,MAX(L12-(D34+D35+D36),0))*E37+MIN(D38,MAX(L12-(D34+D35+D36+D37),0))*E38 -> 1604517.4 | N12: =L12*K12 -> 1648176.6 | O12: =N12-M12 -> 43659.265
A13: SAMPLE-2002 | B13: 1 | C13: 46084 | D13: 592 | E13: 1305.29 | F13: =D13*E13 -> 772731.68 | H13: SAMPLE-2008 | I13: =SUMIFS(Table2[Layer Qty],Table2[SKU],H13) -> 1534 | J13: =SUMIFS(Table2[Layer Total Cost (GHS)],Table2[SKU],H13) -> 2698502.9 | K13: =J13/I13 -> 1759.1284 | L13: =ROUND(I13*0.6,0) -> 920 | M13: =MIN(D39,MAX(L13-(0),0))*E39+MIN(D40,MAX(L13-(D39),0))*E40+MIN(D41,MAX(L13-(D39+D40),0))*E41 -> 1656792 | N13: =L13*K13 -> 1618398.1 | O13: =N13-M13 -> -38393.887
A14: SAMPLE-2002 | B14: 2 | C14: 46169 | D14: 932 | E14: 1190.65 | F14: =D14*E14 -> 1109685.8 | H14: SAMPLE-2009 | I14: =SUMIFS(Table2[Layer Qty],Table2[SKU],H14) -> 1826 | J14: =SUMIFS(Table2[Layer Total Cost (GHS)],Table2[SKU],H14) -> 1301495.9 | K14: =J14/I14 -> 712.75791 | L14: =ROUND(I14*0.6,0) -> 1096 | M14: =MIN(D42,MAX(L14-(0),0))*E42+MIN(D43,MAX(L14-(D42),0))*E43+MIN(D44,MAX(L14-(D42+D43),0))*E44 -> 744644.64 | N14: =L14*K14 -> 781182.67 | O14: =N14-M14 -> 36538.027
A15: SAMPLE-2002 | B15: 3 | C15: 46001 | D15: 89 | E15: 1299.94 | F15: =D15*E15 -> 115694.66 | H15: SAMPLE-2010 | I15: =SUMIFS(Table2[Layer Qty],Table2[SKU],H15) -> 2915 | J15: =SUMIFS(Table2[Layer Total Cost (GHS)],Table2[SKU],H15) -> 4699711.3 | K15: =J15/I15 -> 1612.2509 | L15: =ROUND(I15*0.6,0) -> 1749 | M15: =MIN(D45,MAX(L15-(0),0))*E45+MIN(D46,MAX(L15-(D45),0))*E46+MIN(D47,MAX(L15-(D45+D46),0))*E47+MIN(D48,MAX(L15-(D45+D46+D47),0))*E48+MIN(D49,MAX(L15-(D45+D46+D47+D48),0))*E49 -> 2727941.4 | N15: =L15*K15 -> 2819826.8 | O15: =N15-M15 -> 91885.384
A16: SAMPLE-2002 | B16: 4 | C16: 46254 | D16: 54 | E16: 1395.96 | F16: =D16*E16 -> 75381.84 | H16: SAMPLE-2011 | I16: =SUMIFS(Table2[Layer Qty],Table2[SKU],H16) -> 3401 | J16: =SUMIFS(Table2[Layer Total Cost (GHS)],Table2[SKU],H16) -> 1384225 | K16: =J16/I16 -> 407.00529 | L16: =ROUND(I16*0.6,0) -> 2041 | M16: =MIN(D50,MAX(L16-(0),0))*E50+MIN(D51,MAX(L16-(D50),0))*E51+MIN(D52,MAX(L16-(D50+D51),0))*E52+MIN(D53,MAX(L16-(D50+D51+D52),0))*E53+MIN(D54,MAX(L16-(D50+D51+D52+D53),0))*E54 -> 848864.03 | N16: =L16*K16 -> 830697.8 | O16: =N16-M16 -> -18166.234
A17: SAMPLE-2003 | B17: 1 | C17: 45976 | D17: 917 | E17: 1231.54 | F17: =D17*E17 -> 1129322.2 | H17: SAMPLE-2012 | I17: =SUMIFS(Table2[Layer Qty],Table2[SKU],H17) -> 2265 | J17: =SUMIFS(Table2[Layer Total Cost (GHS)],Table2[SKU],H17) -> 2212431.4 | K17: =J17/I17 -> 976.7909 | L17: =ROUND(I17*0.6,0) -> 1359 | M17: =MIN(D55,MAX(L17-(0),0))*E55+MIN(D56,MAX(L17-(D55),0))*E56+MIN(D57,MAX(L17-(D55+D56),0))*E57+MIN(D58,MAX(L17-(D55+D56+D57),0))*E58+MIN(D59,MAX(L17-(D55+D56+D57+D58),0))*E59 -> 1298887.2 | N17: =L17*K17 -> 1327458.8 | O17: =N17-M17 -> 28571.604
A18: SAMPLE-2003 | B18: 2 | C18: 46063 | D18: 932 | E18: 1543.14 | F18: =D18*E18 -> 1438206.5 | H18: SAMPLE-2013 | I18: =SUMIFS(Table2[Layer Qty],Table2[SKU],H18) -> 1080 | J18: =SUMIFS(Table2[Layer Total Cost (GHS)],Table2[SKU],H18) -> 697493.45 | K18: =J18/I18 -> 645.82727 | L18: =ROUND(I18*0.6,0) -> 648 | M18: =MIN(D60,MAX(L18-(0),0))*E60+MIN(D61,MAX(L18-(D60),0))*E61+MIN(D62,MAX(L18-(D60+D61),0))*E62 -> 453409.13 | N18: =L18*K18 -> 418496.07 | O18: =N18-M18 -> -34913.06
A19: SAMPLE-2003 | B19: 3 | C19: 46246 | D19: 64 | E19: 1401.43 | F19: =D19*E19 -> 89691.52 | H19: SAMPLE-2014 | I19: =SUMIFS(Table2[Layer Qty],Table2[SKU],H19) -> 1649 | J19: =SUMIFS(Table2[Layer Total Cost (GHS)],Table2[SKU],H19) -> 3199068.2 | K19: =J19/I19 -> 1940.005 | L19: =ROUND(I19*0.6,0) -> 989 | M19: =MIN(D63,MAX(L19-(0),0))*E63+MIN(D64,MAX(L19-(D63),0))*E64+MIN(D65,MAX(L19-(D63+D64),0))*E65+MIN(D66,MAX(L19-(D63+D64+D65),0))*E66 -> 1955209.6 | N19: =L19*K19 -> 1918664.9 | O19: =N19-M19 -> -36544.69
A20: SAMPLE-2003 | B20: 4 | C20: 46082 | D20: 669 | E20: 1219.2 | F20: =D20*E20 -> 815644.8 | H20: SAMPLE-2015 | I20: =SUMIFS(Table2[Layer Qty],Table2[SKU],H20) -> 2591 | J20: =SUMIFS(Table2[Layer Total Cost (GHS)],Table2[SKU],H20) -> 5509794.8 | K20: =J20/I20 -> 2126.5129 | L20: =ROUND(I20*0.6,0) -> 1555 | M20: =MIN(D67,MAX(L20-(0),0))*E67+MIN(D68,MAX(L20-(D67),0))*E68+MIN(D69,MAX(L20-(D67+D68),0))*E69+MIN(D70,MAX(L20-(D67+D68+D69),0))*E70+MIN(D71,MAX(L20-(D67+D68+D69+D70),0))*E71 -> 3444221.8 | N20: =L20*K20 -> 3306727.5 | O20: =N20-M20 -> -137494.27
A21: SAMPLE-2003 | B21: 5 | C21: 46228 | D21: 93 | E21: 1419.11 | F21: =D21*E21 -> 131977.23 | H21: SAMPLE-2016 | I21: =SUMIFS(Table2[Layer Qty],Table2[SKU],H21) -> 2553 | J21: =SUMIFS(Table2[Layer Total Cost (GHS)],Table2[SKU],H21) -> 4663610.1 | K21: =J21/I21 -> 1826.7176 | L21: =ROUND(I21*0.6,0) -> 1532 | M21: =MIN(D72,MAX(L21-(0),0))*E72+MIN(D73,MAX(L21-(D72),0))*E73+MIN(D74,MAX(L21-(D72+D73),0))*E74+MIN(D75,MAX(L21-(D72+D73+D74),0))*E75+MIN(D76,MAX(L21-(D72+D73+D74+D75),0))*E76 -> 2698480.1 | N21: =L21*K21 -> 2798531.4 | O21: =N21-M21 -> 100051.3
A22: SAMPLE-2004 | B22: 1 | C22: 46041 | D22: 967 | E22: 1678.91 | F22: =D22*E22 -> 1623506 | H22: SAMPLE-2017 | I22: =SUMIFS(Table2[Layer Qty],Table2[SKU],H22) -> 2379 | J22: =SUMIFS(Table2[Layer Total Cost (GHS)],Table2[SKU],H22) -> 2811189.5 | K22: =J22/I22 -> 1181.6685 | L22: =ROUND(I22*0.6,0) -> 1427 | M22: =MIN(D77,MAX(L22-(0),0))*E77+MIN(D78,MAX(L22-(D77),0))*E78+MIN(D79,MAX(L22-(D77+D78),0))*E79+MIN(D80,MAX(L22-(D77+D78+D79),0))*E80+MIN(D81,MAX(L22-(D77+D78+D79+D80),0))*E81 -> 1617122.6 | N22: =L22*K22 -> 1686241 | O22: =N22-M22 -> 69118.381
A23: SAMPLE-2004 | B23: 2 | C23: 46174 | D23: 311 | E23: 1629.64 | F23: =D23*E23 -> 506818.04 | H23: SAMPLE-2018 | I23: =SUMIFS(Table2[Layer Qty],Table2[SKU],H23) -> 2658 | J23: =SUMIFS(Table2[Layer Total Cost (GHS)],Table2[SKU],H23) -> 4612064.8 | K23: =J23/I23 -> 1735.1636 | L23: =ROUND(I23*0.6,0) -> 1595 | M23: =MIN(D82,MAX(L23-(0),0))*E82+MIN(D83,MAX(L23-(D82),0))*E83+MIN(D84,MAX(L23-(D82+D83),0))*E84+MIN(D85,MAX(L23-(D82+D83+D84),0))*E85+MIN(D86,MAX(L23-(D82+D83+D84+D85),0))*E86 -> 2779901.8 | N23: =L23*K23 -> 2767585.9 | O23: =N23-M23 -> -12315.917
A24: SAMPLE-2004 | B24: 3 | C24: 46233 | D24: 876 | E24: 1646.76 | F24: =D24*E24 -> 1442561.8 | H24: SAMPLE-2019 | I24: =SUMIFS(Table2[Layer Qty],Table2[SKU],H24) -> 2256 | J24: =SUMIFS(Table2[Layer Total Cost (GHS)],Table2[SKU],H24) -> 287150.5 | K24: =J24/I24 -> 127.28302 | L24: =ROUND(I24*0.6,0) -> 1354 | M24: =MIN(D87,MAX(L24-(0),0))*E87+MIN(D88,MAX(L24-(D87),0))*E88+MIN(D89,MAX(L24-(D87+D88),0))*E89+MIN(D90,MAX(L24-(D87+D88+D89),0))*E90 -> 178248.5 | N24: =L24*K24 -> 172341.21 | O24: =N24-M24 -> -5907.2868
A25: SAMPLE-2004 | B25: 4 | C25: 46031 | D25: 332 | E25: 1613.18 | F25: =D25*E25 -> 535575.76 | H25: SAMPLE-2020 | I25: =SUMIFS(Table2[Layer Qty],Table2[SKU],H25) -> 1845 | J25: =SUMIFS(Table2[Layer Total Cost (GHS)],Table2[SKU],H25) -> 2954011.2 | K25: =J25/I25 -> 1601.0901 | L25: =ROUND(I25*0.6,0) -> 1107 | M25: =MIN(D91,MAX(L25-(0),0))*E91+MIN(D92,MAX(L25-(D91),0))*E92+MIN(D93,MAX(L25-(D91+D92),0))*E93+MIN(D94,MAX(L25-(D91+D92+D93),0))*E94 -> 1743454 | N25: =L25*K25 -> 1772406.7 | O25: =N25-M25 -> 28952.744
A26: SAMPLE-2005 | B26: 1 | C26: 46189 | D26: 522 | E26: 1870.16 | F26: =D26*E26 -> 976223.52 | H26: SAMPLE-2021 | I26: =SUMIFS(Table2[Layer Qty],Table2[SKU],H26) -> 3341 | J26: =SUMIFS(Table2[Layer Total Cost (GHS)],Table2[SKU],H26) -> 3822072.4 | K26: =J26/I26 -> 1143.9905 | L26: =ROUND(I26*0.6,0) -> 2005 | M26: =MIN(D95,MAX(L26-(0),0))*E95+MIN(D96,MAX(L26-(D95),0))*E96+MIN(D97,MAX(L26-(D95+D96),0))*E97+MIN(D98,MAX(L26-(D95+D96+D97),0))*E98+MIN(D99,MAX(L26-(D95+D96+D97+D98),0))*E99 -> 2338858.6 | N26: =L26*K26 -> 2293701 | O26: =N26-M26 -> -45157.592
A27: SAMPLE-2005 | B27: 2 | C27: 45967 | D27: 301 | E27: 2315.51 | F27: =D27*E27 -> 696968.51 | H27: SAMPLE-2022 | I27: =SUMIFS(Table2[Layer Qty],Table2[SKU],H27) -> 2040 | J27: =SUMIFS(Table2[Layer Total Cost (GHS)],Table2[SKU],H27) -> 1204499.5 | K27: =J27/I27 -> 590.44094 | L27: =ROUND(I27*0.6,0) -> 1224 | M27: =MIN(D100,MAX(L27-(0),0))*E100+MIN(D101,MAX(L27-(D100),0))*E101+MIN(D102,MAX(L27-(D100+D101),0))*E102 -> 717686.88 | N27: =L27*K27 -> 722699.71 | O27: =N27-M27 -> 5012.832
A28: SAMPLE-2005 | B28: 3 | C28: 46118 | D28: 819 | E28: 2467.04 | F28: =D28*E28 -> 2020505.8 | H28: SAMPLE-2023 | I28: =SUMIFS(Table2[Layer Qty],Table2[SKU],H28) -> 1406 | J28: =SUMIFS(Table2[Layer Total Cost (GHS)],Table2[SKU],H28) -> 2491202.3 | K28: =J28/I28 -> 1771.8366 | L28: =ROUND(I28*0.6,0) -> 844 | M28: =MIN(D103,MAX(L28-(0),0))*E103+MIN(D104,MAX(L28-(D103),0))*E104+MIN(D105,MAX(L28-(D103+D104),0))*E105 -> 1317549.6 | N28: =L28*K28 -> 1495430.1 | O28: =N28-M28 -> 177880.51
A29: SAMPLE-2006 | B29: 1 | C29: 46130 | D29: 912 | E29: 384.4 | F29: =D29*E29 -> 350572.8 | H29: SAMPLE-2024 | I29: =SUMIFS(Table2[Layer Qty],Table2[SKU],H29) -> 1919 | J29: =SUMIFS(Table2[Layer Total Cost (GHS)],Table2[SKU],H29) -> 3900889.6 | K29: =J29/I29 -> 2032.7721 | L29: =ROUND(I29*0.6,0) -> 1151 | M29: =MIN(D106,MAX(L29-(0),0))*E106+MIN(D107,MAX(L29-(D106),0))*E107+MIN(D108,MAX(L29-(D106+D107),0))*E108+MIN(D109,MAX(L29-(D106+D107+D108),0))*E109+MIN(D110,MAX(L29-(D106+D107+D108+D109),0))*E110 -> 2276612.7 | N29: =L29*K29 -> 2339720.6 | O29: =N29-M29 -> 63107.915
A30: SAMPLE-2006 | B30: 2 | C30: 46067 | D30: 646 | E30: 509.97 | F30: =D30*E30 -> 329440.62 | H30: SAMPLE-2025 | I30: =SUMIFS(Table2[Layer Qty],Table2[SKU],H30) -> 1763 | J30: =SUMIFS(Table2[Layer Total Cost (GHS)],Table2[SKU],H30) -> 2357567.4 | K30: =J30/I30 -> 1337.2475 | L30: =ROUND(I30*0.6,0) -> 1058 | M30: =MIN(D111,MAX(L30-(0),0))*E111+MIN(D112,MAX(L30-(D111),0))*E112+MIN(D113,MAX(L30-(D111+D112),0))*E113 -> 1349114.6 | N30: =L30*K30 -> 1414807.9 | O30: =N30-M30 -> 65693.28
A31: SAMPLE-2006 | B31: 3 | C31: 46241 | D31: 687 | E31: 521.86 | F31: =D31*E31 -> 358517.82 | H31: SAMPLE-2026 | I31: =SUMIFS(Table2[Layer Qty],Table2[SKU],H31) -> 2015 | J31: =SUMIFS(Table2[Layer Total Cost (GHS)],Table2[SKU],H31) -> 1452917.4 | K31: =J31/I31 -> 721.05082 | L31: =ROUND(I31*0.6,0) -> 1209 | M31: =MIN(D114,MAX(L31-(0),0))*E114+MIN(D115,MAX(L31-(D114),0))*E115+MIN(D116,MAX(L31-(D114+D115),0))*E116+MIN(D117,MAX(L31-(D114+D115+D116),0))*E117+MIN(D118,MAX(L31-(D114+D115+D116+D117),0))*E118 -> 834267.46 | N31: =L31*K31 -> 871750.45 | O31: =N31-M31 -> 37482.986
A32: SAMPLE-2006 | B32: 4 | C32: 46034 | D32: 980 | E32: 443.34 | F32: =D32*E32 -> 434473.2 | H32: SAMPLE-2027 | I32: =SUMIFS(Table2[Layer Qty],Table2[SKU],H32) -> 2099 | J32: =SUMIFS(Table2[Layer Total Cost (GHS)],Table2[SKU],H32) -> 3187365.4 | K32: =J32/I32 -> 1518.5162 | L32: =ROUND(I32*0.6,0) -> 1259 | M32: =MIN(D119,MAX(L32-(0),0))*E119+MIN(D120,MAX(L32-(D119),0))*E120+MIN(D121,MAX(L32-(D119+D120),0))*E121+MIN(D122,MAX(L32-(D119+D120+D121),0))*E122+MIN(D123,MAX(L32-(D119+D120+D121+D122),0))*E123 -> 1733134.6 | N32: =L32*K32 -> 1911811.9 | O32: =N32-M32 -> 178677.3
A33: SAMPLE-2006 | B33: 5 | C33: 46254 | D33: 467 | E33: 522.42 | F33: =D33*E33 -> 243970.14 | H33: SAMPLE-2028 | I33: =SUMIFS(Table2[Layer Qty],Table2[SKU],H33) -> 2065 | J33: =SUMIFS(Table2[Layer Total Cost (GHS)],Table2[SKU],H33) -> 3227703.6 | K33: =J33/I33 -> 1563.0526 | L33: =ROUND(I33*0.6,0) -> 1239 | M33: =MIN(D124,MAX(L33-(0),0))*E124+MIN(D125,MAX(L33-(D124),0))*E125+MIN(D126,MAX(L33-(D124+D125),0))*E126 -> 1919848.6 | N33: =L33*K33 -> 1936622.2 | O33: =N33-M33 -> 16773.624
A34: SAMPLE-2007 | B34: 1 | C34: 46103 | D34: 952 | E34: 1066.79 | F34: =D34*E34 -> 1015584.1 | H34: SAMPLE-2029 | I34: =SUMIFS(Table2[Layer Qty],Table2[SKU],H34) -> 3024 | J34: =SUMIFS(Table2[Layer Total Cost (GHS)],Table2[SKU],H34) -> 1232264.3 | K34: =J34/I34 -> 407.49482 | L34: =ROUND(I34*0.6,0) -> 1814 | M34: =MIN(D127,MAX(L34-(0),0))*E127+MIN(D128,MAX(L34-(D127),0))*E128+MIN(D129,MAX(L34-(D127+D128),0))*E129+MIN(D130,MAX(L34-(D127+D128+D129),0))*E130+MIN(D131,MAX(L34-(D127+D128+D129+D130),0))*E131 -> 741173.83 | N34: =L34*K34 -> 739195.6 | O34: =N34-M34 -> -1978.2299
A35: SAMPLE-2007 | B35: 2 | C35: 46179 | D35: 528 | E35: 1247.74 | F35: =D35*E35 -> 658806.72 | H35: SAMPLE-2030 | I35: =SUMIFS(Table2[Layer Qty],Table2[SKU],H35) -> 1173 | J35: =SUMIFS(Table2[Layer Total Cost (GHS)],Table2[SKU],H35) -> 661416.76 | K35: =J35/I35 -> 563.86766 | L35: =ROUND(I35*0.6,0) -> 704 | M35: =MIN(D132,MAX(L35-(0),0))*E132+MIN(D133,MAX(L35-(D132),0))*E133+MIN(D134,MAX(L35-(D132+D133),0))*E134+MIN(D135,MAX(L35-(D132+D133+D134),0))*E135+MIN(D136,MAX(L35-(D132+D133+D134+D135),0))*E136 -> 384048.29 | N35: =L35*K35 -> 396962.83 | O35: =N35-M35 -> 12914.54
A36: SAMPLE-2007 | B36: 3 | C36: 46184 | D36: 240 | E36: 1013.73 | F36: =D36*E36 -> 243295.2 | H36: SAMPLE-2031 | I36: =SUMIFS(Table2[Layer Qty],Table2[SKU],H36) -> 2029 | J36: =SUMIFS(Table2[Layer Total Cost (GHS)],Table2[SKU],H36) -> 1236368.9 | K36: =J36/I36 -> 609.34887 | L36: =ROUND(I36*0.6,0) -> 1217 | M36: =MIN(D137,MAX(L36-(0),0))*E137+MIN(D138,MAX(L36-(D137),0))*E138+MIN(D139,MAX(L36-(D137+D138),0))*E139+MIN(D140,MAX(L36-(D137+D138+D139),0))*E140 -> 688601.25 | N36: =L36*K36 -> 741577.57 | O36: =N36-M36 -> 52976.32
A37: SAMPLE-2007 | B37: 4 | C37: 46229 | D37: 384 | E37: 1372.54 | F37: =D37*E37 -> 527055.36 | H37: SAMPLE-2032 | I37: =SUMIFS(Table2[Layer Qty],Table2[SKU],H37) -> 2213 | J37: =SUMIFS(Table2[Layer Total Cost (GHS)],Table2[SKU],H37) -> 274480.44 | K37: =J37/I37 -> 124.03093 | L37: =ROUND(I37*0.6,0) -> 1328 | M37: =MIN(D141,MAX(L37-(0),0))*E141+MIN(D142,MAX(L37-(D141),0))*E142+MIN(D143,MAX(L37-(D141+D142),0))*E143+MIN(D144,MAX(L37-(D141+D142+D143),0))*E144+MIN(D145,MAX(L37-(D141+D142+D143+D144),0))*E145 -> 165802.66 | N37: =L37*K37 -> 164713.07 | O37: =N37-M37 -> -1089.5898
A38: SAMPLE-2007 | B38: 5 | C38: 46103 | D38: 270 | E38: 1122.19 | F38: =D38*E38 -> 302991.3 | H38: SAMPLE-2033 | I38: =SUMIFS(Table2[Layer Qty],Table2[SKU],H38) -> 2340 | J38: =SUMIFS(Table2[Layer Total Cost (GHS)],Table2[SKU],H38) -> 617505.25 | K38: =J38/I38 -> 263.89113 | L38: =ROUND(I38*0.6,0) -> 1404 | M38: =MIN(D146,MAX(L38-(0),0))*E146+MIN(D147,MAX(L38-(D146),0))*E147+MIN(D148,MAX(L38-(D146+D147),0))*E148+MIN(D149,MAX(L38-(D146+D147+D148),0))*E149+MIN(D150,MAX(L38-(D146+D147+D148+D149),0))*E150 -> 334367.58 | N38: =L38*K38 -> 370503.15 | O38: =N38-M38 -> 36135.57
A39: SAMPLE-2008 | B39: 1 | C39: 46074 | D39: 608 | E39: 1949.79 | F39: =D39*E39 -> 1185472.3 | H39: SAMPLE-2034 | I39: =SUMIFS(Table2[Layer Qty],Table2[SKU],H39) -> 1879 | J39: =SUMIFS(Table2[Layer Total Cost (GHS)],Table2[SKU],H39) -> 821501.99 | K39: =J39/I39 -> 437.2017 | L39: =ROUND(I39*0.6,0) -> 1127 | M39: =MIN(D151,MAX(L39-(0),0))*E151+MIN(D152,MAX(L39-(D151),0))*E152+MIN(D153,MAX(L39-(D151+D152),0))*E153 -> 477439.43 | N39: =L39*K39 -> 492726.31 | O39: =N39-M39 -> 15286.883
A40: SAMPLE-2008 | B40: 2 | C40: 46239 | D40: 513 | E40: 1510.64 | F40: =D40*E40 -> 774958.32 | H40: SAMPLE-2035 | I40: =SUMIFS(Table2[Layer Qty],Table2[SKU],H40) -> 1931 | J40: =SUMIFS(Table2[Layer Total Cost (GHS)],Table2[SKU],H40) -> 1626412.2 | K40: =J40/I40 -> 842.26423 | L40: =ROUND(I40*0.6,0) -> 1159 | M40: =MIN(D154,MAX(L40-(0),0))*E154+MIN(D155,MAX(L40-(D154),0))*E155+MIN(D156,MAX(L40-(D154+D155),0))*E156+MIN(D157,MAX(L40-(D154+D155+D156),0))*E157 -> 1023318.3 | N40: =L40*K40 -> 976184.24 | O40: =N40-M40 -> -47134.046
...

Sheet Standard Costing & Variances
A1: Standard Costing - Purchase Price and Usage Variances (Manufacturing)
A2: Standard cost approximates actual cost. Variances are allocated between COGS and inventory at period end per the closing-inventory proportion of total issues.
A4: Material | B4: Standard Qty | C4: Standard Price (GHS) | D4: Actual Qty | E4: Actual Price (GHS) | F4: Price Variance (GHS) | G4: Usage Variance (GHS) | H4: Total Variance (GHS) | I4: Closing Inventory % of Issues | J4: Variance to Inventory (GHS) | K4: Variance to COGS (GHS)
A5: Steel Coil #1 | B5: 4228 | C5: 278.17 | D5: 4192 | E5: 318.95 | F5: =(E5-C5)*D5 -> 170949.76 | G5: =(D5-B5)*C5 -> -10014.12 | H5: =F5+G5 -> 160935.64 | I5: 0.2719 | J5: =H5*I5 -> 43758.401 | K5: =H5-J5 -> 117177.24
A6: Resin Pellets #2 | B6: 14870 | C6: 374.33 | D6: 13972 | E6: 360.91 | F6: =(E6-C6)*D6 -> -187504.24 | G6: =(D6-B6)*C6 -> -336148.34 | H6: =F6+G6 -> -523652.58 | I6: 0.1964 | J6: =H6*I6 -> -102845.37 | K6: =H6-J6 -> -420807.21
A7: Packaging Film #3 | B7: 1098 | C7: 74.41 | D7: 1120 | E7: 83.62 | F7: =(E7-C7)*D7 -> 10315.2 | G7: =(D7-B7)*C7 -> 1637.02 | H7: =F7+G7 -> 11952.22 | I7: 0.2613 | J7: =H7*I7 -> 3123.1151 | K7: =H7-J7 -> 8829.1049
A8: Aluminium Sheet #4 | B8: 5079 | C8: 374.65 | D8: 5120 | E8: 406.11 | F8: =(E8-C8)*D8 -> 161075.2 | G8: =(D8-B8)*C8 -> 15360.65 | H8: =F8+G8 -> 176435.85 | I8: 0.1381 | J8: =H8*I8 -> 24365.791 | K8: =H8-J8 -> 152070.06
A9: Copper Wire #5 | B9: 9481 | C9: 150.26 | D9: 10124 | E9: 164.55 | F9: =(E9-C9)*D9 -> 144671.96 | G9: =(D9-B9)*C9 -> 96617.18 | H9: =F9+G9 -> 241289.14 | I9: 0.1093 | J9: =H9*I9 -> 26372.903 | K9: =H9-J9 -> 214916.24
A10: Corrugated Board #6 | B10: 15043 | C10: 107.86 | D10: 15152 | E10: 116.59 | F10: =(E10-C10)*D10 -> 132276.96 | G10: =(D10-B10)*C10 -> 11756.74 | H10: =F10+G10 -> 144033.7 | I10: 0.0819 | J10: =H10*I10 -> 11796.36 | K10: =H10-J10 -> 132237.34
A11: PET Preform #7 | B11: 9756 | C11: 275.13 | D11: 10575 | E11: 270.62 | F11: =(E11-C11)*D11 -> -47693.25 | G11: =(D11-B11)*C11 -> 225331.47 | H11: =F11+G11 -> 177638.22 | I11: 0.2221 | J11: =H11*I11 -> 39453.449 | K11: =H11-J11 -> 138184.77
A12: Glass Cullet #8 | B12: 5734 | C12: 320.02 | D12: 5826 | E12: 365.25 | F12: =(E12-C12)*D12 -> 263509.98 | G12: =(D12-B12)*C12 -> 29441.84 | H12: =F12+G12 -> 292951.82 | I12: 0.1228 | J12: =H12*I12 -> 35974.483 | K12: =H12-J12 -> 256977.34
A13: Cement Clinker #9 | B13: 6165 | C13: 287.21 | D13: 6831 | E13: 329.71 | F13: =(E13-C13)*D13 -> 290317.5 | G13: =(D13-B13)*C13 -> 191281.86 | H13: =F13+G13 -> 481599.36 | I13: 0.3438 | J13: =H13*I13 -> 165573.86 | K13: =H13-J13 -> 316025.5
A14: Timber Board #10 | B14: 8316 | C14: 173.43 | D14: 8724 | E14: 173.5 | F14: =(E14-C14)*D14 -> 610.68 | G14: =(D14-B14)*C14 -> 70759.44 | H14: =F14+G14 -> 71370.12 | I14: 0.0991 | J14: =H14*I14 -> 7072.7789 | K14: =H14-J14 -> 64297.341
A15: Steel Coil #11 | B15: 11307 | C15: 126 | D15: 12144 | E15: 143.49 | F15: =(E15-C15)*D15 -> 212398.56 | G15: =(D15-B15)*C15 -> 105462 | H15: =F15+G15 -> 317860.56 | I15: 0.2971 | J15: =H15*I15 -> 94436.372 | K15: =H15-J15 -> 223424.19
A16: Resin Pellets #12 | B16: 18442 | C16: 375.2 | D16: 17084 | E16: 335.89 | F16: =(E16-C16)*D16 -> -671572.04 | G16: =(D16-B16)*C16 -> -509521.6 | H16: =F16+G16 -> -1181093.6 | I16: 0.2755 | J16: =H16*I16 -> -325391.3 | K16: =H16-J16 -> -855702.34
... A304: Timber Board #300 | B304: 14139 | C304: 306.31 | D304: 15063 | E304: 341.21 | F304: =(E304-C304)*D304 -> 525698.7 | G304: =(D304-B304)*C304 -> 283030.44 | H304: =F304+G304 -> 808729.14 | I304: 0.1988 | J304: =H304*I304 -> 160775.35 | K304: =H304-J304 -> 647953.79

Sheet Consignment & Cutoff
A1: Consignment Inventory Summary & Period-End Cutoff Testing
A3: Consignment Summary (from Inventory Register)
A4: Consignment Status | B4: Count | C4: Total Cost (GHS)
A5: Owned | B5: =COUNTIF('Inventory Register'!$T$2:$T$10501,A5) -> 9236 | C5: =SUMIF('Inventory Register'!$T$2:$T$10501,A5,'Inventory Register'!$I$2:$I$10501) -> 2.4939484e+12
A6: Held on Consignment (Not Owned) | B6: =COUNTIF('Inventory Register'!$T$2:$T$10501,A6) -> 755 | C6: =SUMIF('Inventory Register'!$T$2:$T$10501,A6,'Inventory Register'!$I$2:$I$10501) -> 2.1708115e+11
A7: Owned, Held Externally | B7: =COUNTIF('Inventory Register'!$T$2:$T$10501,A7) -> 509 | C7: =SUMIF('Inventory Register'!$T$2:$T$10501,A7,'Inventory Register'!$I$2:$I$10501) -> 1.304174e+11
A10: Period-End Cutoff Test (transactions around period end)
A11: Transaction ID | B11: Invoice Date | C11: Shipping Date | D11: FOB Terms | E11: Recorded In Period | F11: Correct Period (per FOB terms) | G11: Cutoff Error?
A12: TXN-3000 | B12: 46210 | C12: 46209 | D12: FOB Destination | E12: Next | F12: =IF(D12="FOB Shipping Point",IF(C12<=DATE(2026,6,30),"Current","Next"),IF(C12+3<=DATE(2026,6,30),"Current","Next")) -> Next | G12: =IF(E12<>F12,"ERROR","OK") -> OK
A13: TXN-3001 | B13: 46210 | C13: 46208 | D13: FOB Destination | E13: Next | F13: =IF(D13="FOB Shipping Point",IF(C13<=DATE(2026,6,30),"Current","Next"),IF(C13+3<=DATE(2026,6,30),"Current","Next")) -> Next | G13: =IF(E13<>F13,"ERROR","OK") -> OK
A14: TXN-3002 | B14: 46212 | C14: 46209 | D14: FOB Shipping Point | E14: Next | F14: =IF(D14="FOB Shipping Point",IF(C14<=DATE(2026,6,30),"Current","Next"),IF(C14+3<=DATE(2026,6,30),"Current","Next")) -> Next | G14: =IF(E14<>F14,"ERROR","OK") -> OK
A15: TXN-3003 | B15: 46200 | C15: 46200 | D15: FOB Destination | E15: Current | F15: =IF(D15="FOB Shipping Point",IF(C15<=DATE(2026,6,30),"Current","Next"),IF(C15+3<=DATE(2026,6,30),"Current","Next")) -> Current | G15: =IF(E15<>F15,"ERROR","OK") -> OK
A16: TXN-3004 | B16: 46206 | C16: 46205 | D16: FOB Destination | E16: Next | F16: =IF(D16="FOB Shipping Point",IF(C16<=DATE(2026,6,30),"Current","Next"),IF(C16+3<=DATE(2026,6,30),"Current","Next")) -> Next | G16: =IF(E16<>F16,"ERROR","OK") -> OK
A17: TXN-3005 | B17: 46209 | C17: 46209 | D17: FOB Shipping Point | E17: Next | F17: =IF(D17="FOB Shipping Point",IF(C17<=DATE(2026,6,30),"Current","Next"),IF(C17+3<=DATE(2026,6,30),"Current","Next")) -> Next | G17: =IF(E17<>F17,"ERROR","OK") -> OK
A18: TXN-3006 | B18: 46201 | C18: 46198 | D18: FOB Destination | E18: Current | F18: =IF(D18="FOB Shipping Point",IF(C18<=DATE(2026,6,30),"Current","Next"),IF(C18+3<=DATE(2026,6,30),"Current","Next")) -> Current | G18: =IF(E18<>F18,"ERROR","OK") -> OK
A19: TXN-3007 | B19: 46199 | C19: 46199 | D19: FOB Destination | E19: Current | F19: =IF(D19="FOB Shipping Point",IF(C19<=DATE(2026,6,30),"Current","Next"),IF(C19+3<=DATE(2026,6,30),"Current","Next")) -> Current | G19: =IF(E19<>F19,"ERROR","OK") -> OK
A20: TXN-3008 | B20: 46214 | C20: 46211 | D20: FOB Destination | E20: Next | F20: =IF(D20="FOB Shipping Point",IF(C20<=DATE(2026,6,30),"Current","Next"),IF(C20+3<=DATE(2026,6,30),"Current","Next")) -> Next | G20: =IF(E20<>F20,"ERROR","OK") -> OK
A21: TXN-3009 | B21: 46200 | C21: 46199 | D21: FOB Shipping Point | E21: Current | F21: =IF(D21="FOB Shipping Point",IF(C21<=DATE(2026,6,30),"Current","Next"),IF(C21+3<=DATE(2026,6,30),"Current","Next")) -> Current | G21: =IF(E21<>F21,"ERROR","OK") -> OK
A22: TXN-3010 | B22: 46201 | C22: 46201 | D22: FOB Shipping Point | E22: Current | F22: =IF(D22="FOB Shipping Point",IF(C22<=DATE(2026,6,30),"Current","Next"),IF(C22+3<=DATE(2026,6,30),"Current","Next")) -> Current | G22: =IF(E22<>F22,"ERROR","OK") -> OK
A23: TXN-3011 | B23: 46210 | C23: 46208 | D23: FOB Destination | E23: Next | F23: =IF(D23="FOB Shipping Point",IF(C23<=DATE(2026,6,30),"Current","Next"),IF(C23+3<=DATE(2026,6,30),"Current","Next")) -> Next | G23: =IF(E23<>F23,"ERROR","OK") -> OK
... A71: TXN-3059 | B71: 46207 | C71: 46205 | D71: FOB Destination | E71: Next | F71: =IF(D71="FOB Shipping Point",IF(C71<=DATE(2026,6,30),"Current","Next"),IF(C71+3<=DATE(2026,6,30),"Current","Next")) -> Next | G71: =IF(E71<>F71,"ERROR","OK") -> OK

Sheet Intercompany Elimination
A1: Intercompany Sales - Unrealized Profit Elimination on Consolidation
A2: Unrealized profit sitting in the buyer's closing inventory from an intragroup sale is eliminated on consolidation - it hasn't been realized through a sale to an external party.
A4: Transaction | B4: Selling Group Entity | C4: Buying Group Entity | D4: Intercompany Sale Price (GHS) | E4: Seller's Cost (GHS) | F4: Markup % on Cost | G4: Qty Sold Intercompany | H4: Qty Still in Buyer's Closing Inventory | I4: % Still on Hand | J4: Unrealized Profit to Eliminate (GHS)
A5: IC-4000 | B5: Accra Distribution Ltd | C5: Kumasi Retail Ltd | D5: 564193 | E5: =D5/(1+F5) -> 476192.61 | F5: 0.1848 | G5: 4774 | H5: 2712 | I5: =H5/G5 -> 0.56807708 | J5: =(D5-E5)*I5 -> 49991.007
A6: IC-4001 | B6: Takoradi Processing Ltd | C6: Tema Manufacturing Ltd | D6: 77219 | E6: =D6/(1+F6) -> 59417.513 | F6: 0.2996 | G6: 4409 | H6: 2596 | I6: =H6/G6 -> 0.58879565 | J6: =(D6-E6)*I6 -> 10481.438
A7: IC-4002 | B7: Kumasi Retail Ltd | C7: Takoradi Processing Ltd | D7: 731951 | E7: =D7/(1+F7) -> 659890.91 | F7: 0.1092 | G7: 5863 | H7: 2200 | I7: =H7/G7 -> 0.37523452 | J7: =(D7-E7)*I7 -> 27039.433
A8: IC-4003 | B8: Takoradi Processing Ltd | C8: Kumasi Retail Ltd | D8: 804960 | E8: =D8/(1+F8) -> 686064.95 | F8: 0.1733 | G8: 5022 | H8: 2522 | I8: =H8/G8 -> 0.50219036 | J8: =(D8-E8)*I8 -> 59707.951
A9: IC-4004 | B9: Takoradi Processing Ltd | C9: Accra Distribution Ltd | D9: 880154 | E9: =D9/(1+F9) -> 672129.82 | F9: 0.3095 | G9: 2455 | H9: 524 | I9: =H9/G9 -> 0.21344196 | J9: =(D9-E9)*I9 -> 44401.088
A10: IC-4005 | B10: Accra Distribution Ltd | C10: Kumasi Retail Ltd | D10: 270039 | E10: =D10/(1+F10) -> 229761.76 | F10: 0.1753 | G10: 2034 | H10: 1110 | I10: =H10/G10 -> 0.54572271 | J10: =(D10-E10)*I10 -> 21980.203
A11: IC-4006 | B11: Tema Manufacturing Ltd | C11: Accra Distribution Ltd | D11: 105963 | E11: =D11/(1+F11) -> 81166.603 | F11: 0.3055 | G11: 7970 | H11: 2573 | I11: =H11/G11 -> 0.32283563 | J11: =(D11-E11)*I11 -> 8005.1606
A12: IC-4007 | B12: Accra Distribution Ltd | C12: Takoradi Processing Ltd | D12: 286222 | E12: =D12/(1+F12) -> 250500.61 | F12: 0.1426 | G12: 1463 | H12: 706 | I12: =H12/G12 -> 0.48257006 | J12: =(D12-E12)*I12 -> 17238.072
A13: IC-4008 | B13: Tema Manufacturing Ltd | C13: Accra Distribution Ltd | D13: 399890 | E13: =D13/(1+F13) -> 358452.85 | F13: 0.1156 | G13: 1271 | H13: 753 | I13: =H13/G13 -> 0.59244689 | J13: =(D13-E13)*I13 -> 24549.31
A14: IC-4009 | B14: Takoradi Processing Ltd | C14: Tema Manufacturing Ltd | D14: 198265 | E14: =D14/(1+F14) -> 179636.68 | F14: 0.1037 | G14: 2432 | H14: 1216 | I14: =H14/G14 -> 0.5 | J14: =(D14-E14)*I14 -> 9314.1617
A15: IC-4010 | B15: Takoradi Processing Ltd | C15: Kumasi Retail Ltd | D15: 174916 | E15: =D15/(1+F15) -> 131357.77 | F15: 0.3316 | G15: 2776 | H15: 976 | I15: =H15/G15 -> 0.35158501 | J15: =(D15-E15)*I15 -> 15314.423
A16: IC-4011 | B16: Kumasi Retail Ltd | C16: Takoradi Processing Ltd | D16: 650356 | E16: =D16/(1+F16) -> 503293.61 | F16: 0.2922 | G16: 730 | H16: 394 | I16: =H16/G16 -> 0.53972603 | J16: =(D16-E16)*I16 -> 79373.401
... A29: IC-4024 | B29: Accra Distribution Ltd | C29: Takoradi Processing Ltd | D29: 722374 | E29: =D29/(1+F29) -> 564840.1 | F29: 0.2789 | G29: 2175 | H29: 1179 | I29: =H29/G29 -> 0.54206897 | J29: =(D29-E29)*I29 -> 85394.24

Sheet Pledged Collateral
A1: Inventory Pledged as Loan Collateral (IAS 2.36(g) Disclosure)
A2: Summarizes pledged inventory from the register against the facilities it secures.
A4: Metric | B4: Value
A5: Total inventory pledged as collateral (GHS) | B5: =SUMIF('Inventory Register'!$U$2:$U$10501,"Yes",'Inventory Register'!$I$2:$I$10501) -> 4.7638775e+11
A6: Total inventory NOT pledged (GHS) | B6: =SUMIF('Inventory Register'!$U$2:$U$10501,"No",'Inventory Register'!$I$2:$I$10501) -> 2.3650592e+12
A7: Total inventory (GHS) | B7: =SUM('Inventory Register'!$I$2:$I$10501) -> 2.8414469e+12
A10: Facilities Secured Against Pledged Inventory (illustrative)
A11: Lender | B11: Facility Type | C11: Facility Limit (GHS) | D11: Amount Drawn (GHS) | E11: Collateral Coverage Ratio
A12: GCB Bank | B12: Warehouse Receipt Facility | C12: 45000000 | D12: 32000000 | E12: =$B$5/D12 -> 14887.117
A13: Absa Ghana | B13: Inventory-Backed Overdraft | C13: 28000000 | D13: 19500000 | E13: =$B$5/D13 -> 24430.141
A14: Stanbic Bank | B14: Trade Finance Facility | C14: 60000000 | D14: 41000000 | E14: =$B$5/D14 -> 11619.213

Sheet Borrowing Cost Capitalization
A1: Borrowing Cost Capitalization on Qualifying Inventory (IAS 23)
A2: Applies to long-cycle development inventory (Real Estate Developer profile) that takes a substantial period to prepare for sale. Capitalization is suspended during extended interruptions.
A4: Development Project | B4: Eligible Expenditure (GHS) | C4: Capitalization Rate | D4: Months Active This Period | E4: Extended Interruption This Period? | F4: Capitalized Borrowing Cost (GHS)
A5: East Legon Residential Phase 2 | B5: 74477848 | C5: 0.1088 | D5: 10 | E5: Yes | F5: =B5*C5*(D5/12) -> 6752658.2
A6: Airport City Mixed-Use Tower | B6: 34323050 | C6: 0.1048 | D6: 12 | E6: No | F6: =B6*C6*(D6/12) -> 3597055.6
A7: Trasacco Valley Extension | B7: 51442718 | C7: 0.1129 | D7: 11 | E7: No | F7: =B7*C7*(D7/12) -> 5323892.6
A8: Spintex Retail & Residential | B8: 20416056 | C8: 0.1131 | D8: 12 | E8: No | F8: =B8*C8*(D8/12) -> 2309055.9
A9: Tema Community 25 Estate | B9: 51450726 | C9: 0.1166 | D9: 8 | E9: Yes | F9: =B9*C9*(D9/12) -> 3999436.4

Sheet Disclosures Summary
A1: Inventory Note Disclosures (IAS 2.36)
A3: Disclosure Item | B3: Amount / Value (GHS)
A4: Total carrying amount of inventories | B4: =SUM('Inventory Register'!$I$2:$I$10501)-SUM('Inventory Register'!$R$2:$R$10501) -> 2.4126653e+12
A5: Total inventory write-down (provision) recognized as expense | B5: =SUM('Inventory Register'!$R$2:$R$10501) -> 4.2878159e+11
A6: Total carrying amount of inventories pledged as security | B6: =SUMIF('Inventory Register'!$U$2:$U$10501,"Yes",'Inventory Register'!$I$2:$I$10501) -> 4.7638775e+11
A7: Carrying amount of inventories carried at fair value less costs to sell | B7: =SUMIF('Inventory Register'!$B$2:$B$10501,"Agribusiness/Commodity",'Inventory Register'!$I$2:$I$10501) -> 4.0731623e+11
A8: Cost formula(s) used | B8: See Assumptions - Industry Profile Parameters (varies by profile: Weighted Average, FIFO, Specific Identification, Fair Value Less Costs to Sell)
A10: Carrying Amount by Industry Profile
A11: Industry Profile | B11: Carrying Amount (GHS)
A12: Manufacturing | B12: =SUMIF('Inventory Register'!$B$2:$B$10501,A12,'Inventory Register'!$S$2:$S$10501) -> 1.2134249e+10
A13: Retail/FMCG | B13: =SUMIF('Inventory Register'!$B$2:$B$10501,A13,'Inventory Register'!$S$2:$S$10501) -> 1.9357374e+09
A14: Real Estate Developer | B14: =SUMIF('Inventory Register'!$B$2:$B$10501,A14,'Inventory Register'!$S$2:$S$10501) -> 1.2707829e+12
A15: Agribusiness/Commodity | B15: =SUMIF('Inventory Register'!$B$2:$B$10501,A15,'Inventory Register'!$S$2:$S$10501) -> 3.0084035e+11
A16: Extractives | B16: =SUMIF('Inventory Register'!$B$2:$B$10501,A16,'Inventory Register'!$S$2:$S$10501) -> 6.4305509e+11

Sheet Visualizations
A1: IAS 2 Model - Visualizations
A4: Inventory Value by Aging Bucket
A5: Bucket | B5: Carrying Amount (GHS)
A6: 0-90d | B6: =SUMIF('Inventory Register'!$P$2:$P$10501,A6,'Inventory Register'!$S$2:$S$10501) -> 1.9862194e+11
A7: 91-180d | B7: =SUMIF('Inventory Register'!$P$2:$P$10501,A7,'Inventory Register'!$S$2:$S$10501) -> 4.2156659e+11
A8: 181-365d | B8: =SUMIF('Inventory Register'!$P$2:$P$10501,A8,'Inventory Register'!$S$2:$S$10501) -> 9.2994246e+11
A9: 365d+ | B9: =SUMIF('Inventory Register'!$P$2:$P$10501,A9,'Inventory Register'!$S$2:$S$10501) -> 6.7861735e+11
A12: Inventory Write-Down by Industry Profile
A13: Profile | B13: Write-Down (GHS)
A14: Manufacturing | B14: =SUMIF('Inventory Register'!$B$2:$B$10501,A14,'Inventory Register'!$R$2:$R$10501) -> 6.0402275e+09
A15: Retail/FMCG | B15: =SUMIF('Inventory Register'!$B$2:$B$10501,A15,'Inventory Register'!$R$2:$R$10501) -> 1.7830047e+09
A16: Real Estate Developer | B16: =SUMIF('Inventory Register'!$B$2:$B$10501,A16,'Inventory Register'!$R$2:$R$10501) -> 1.0999057e+11
A17: Agribusiness/Commodity | B17: =SUMIF('Inventory Register'!$B$2:$B$10501,A17,'Inventory Register'!$R$2:$R$10501) -> 7.8990623e+10
A18: Extractives | B18: =SUMIF('Inventory Register'!$B$2:$B$10501,A18,'Inventory Register'!$R$2:$R$10501) -> 2.3197716e+11
A21: FIFO vs Weighted Average - Sample Variance Summary
A22: Metric | B22: Value (GHS)
A23: Total FIFO Issue Cost (sample) | B23: =SUM('FIFO vs Weighted Avg'!M5:M154) -> 2.0739588e+08
A24: Total Weighted Avg Issue Cost (sample) | B24: =SUM('FIFO vs Weighted Avg'!N5:N154) -> 2.1226352e+08
A27: COGS Build Waterfall (Illustrative)
A28: Component | B28: Amount (GHS)
A29: Opening Inventory (illustrative, 90% of closing) | B29: =SUM('Inventory Register'!$S$2:$S$10501)*0.9 -> 2.0058735e+12
A30: Purchases (illustrative, 110% of closing) | B30: =SUM('Inventory Register'!$S$2:$S$10501)*1.1 -> 2.4516232e+12
A31: Closing Inventory | B31: =SUM('Inventory Register'!$S$2:$S$10501) -> 2.2287483e+12
A32: COGS (Opening + Purchases - Closing) | B32: =B29+B30-B31 -> 2.2287483e+12
A35: Inventory Carrying Value by Industry Profile
A36: Profile | B36: Carrying Amount (GHS)
A37: Manufacturing | B37: =SUMIF('Inventory Register'!$B$2:$B$10501,A37,'Inventory Register'!$S$2:$S$10501) -> 1.2134249e+10
A38: Retail/FMCG | B38: =SUMIF('Inventory Register'!$B$2:$B$10501,A38,'Inventory Register'!$S$2:$S$10501) -> 1.9357374e+09
A39: Real Estate Developer | B39: =SUMIF('Inventory Register'!$B$2:$B$10501,A39,'Inventory Register'!$S$2:$S$10501) -> 1.2707829e+12
A40: Agribusiness/Commodity | B40: =SUMIF('Inventory Register'!$B$2:$B$10501,A40,'Inventory Register'!$S$2:$S$10501) -> 3.0084035e+11
A41: Extractives | B41: =SUMIF('Inventory Register'!$B$2:$B$10501,A41,'Inventory Register'!$S$2:$S$10501) -> 6.4305509e+11

Sheet Checks & Audit
A1: IAS 2 Model - Audit Checks
A3: Check | B3: Result
A4: No negative inventory carrying amounts | B4: =IF(MIN('Inventory Register'!$S$2:$S$10501)>=0,"PASS","FAIL") -> PASS
A5: Cost formula consistently applied within each profile (single method per profile) | B5: =IF(COUNTA(Assumptions!B8:B12)=5,"PASS","FAIL") -> PASS
A6: NRV tested item-by-item (not by total class) - confirmed by row-level formula design | B6: ="PASS" -> PASS
A7: Cutoff testing performed for period-end transactions | B7: =IF(COUNTIF('Consignment & Cutoff'!G12:G71,"ERROR")>=0,"PASS (errors flagged where found)","FAIL") -> PASS (errors flagged where found)
A8: Pledged inventory does not exceed total inventory on hand | B8: =IF('Pledged Collateral'!B5<='Pledged Collateral'!B7,"PASS","FAIL") -> PASS
A9: Capitalized borrowing cost does not exceed a reasonable cap of eligible expenditure | B9: {=IF(SUMPRODUCT(('Borrowing Cost Capitalization'!F5:F9)<=('Borrowing Cost Capitalization'!B5:B9*0.15))=COUNT('Borrowing Cost Capitalization'!F5:F9),"PASS","FAIL")} -> FAIL
A10: Industry profile parameters fully populated (no hidden hard-coded values) | B10: =IF(COUNTBLANK(Assumptions!B8:H12)=0,"PASS","FAIL") -> PASS
A12: Overall audit status | B12: =IF(COUNTIF(B4:B10,"FAIL")=0,"PASS","FAIL") -> FAIL

Sheet Glossary
A1: Glossary
A3: A. Technical / Standards Terms
A4: NRV | B4: Net realizable value - estimated selling price less costs to complete and costs to sell.
A5: Cost of conversion | B5: Direct labour plus systematically allocated production overhead.
A6: Normal capacity | B6: The production expected to be achieved under normal circumstances, used to allocate fixed overhead.
A7: NRV reversal | B7: A previously recognized write-down is reversed (up to original cost) if NRV subsequently recovers.
A8: Consignment inventory | B8: Goods held by one party but owned by another; only the owner recognizes it as inventory.
A9: Cutoff | B9: Ensuring a transaction is recorded in the correct accounting period based on when risks/rewards transferred.
A11: B. Practical / Industry Terms
A12: SKU | B12: Stock-keeping unit - a distinct trackable inventory item.
A13: Shrinkage | B13: Inventory loss from theft, damage, or spoilage.
A14: Standard cost | B14: A predetermined cost used for planning and control, compared against actual cost via variances.
A15: Purchase price variance | B15: The difference between actual and standard price, multiplied by actual quantity purchased.
A16: Usage variance | B16: The difference between actual and standard quantity used, multiplied by standard price.
A17: Byproduct | B17: A secondary product of lesser value arising from a joint production process.
A18: Warehouse receipt financing | B18: Borrowing secured against a warehouse receipt evidencing stored, pledged inventory.
